<?xml version="1.0" ?>
<!-- =================================================================================== -->
<!-- |    This document was autogenerated by xacro from clearpath/robot.urdf.xacro     | -->
<!-- |    EDITING THIS FILE BY HAND IS NOT RECOMMENDED                                 | -->
<!-- =================================================================================== -->
<robot name="r100-0600" xmlns:ignition="http://gazebosim.org/schema">
  <material name="clearpath_dark_grey">
    <color rgba="0.2 0.2 0.2 1.0"/>
  </material>
  <material name="clearpath_medium_grey">
    <color rgba="0.6 0.6 0.6 1.0"/>
  </material>
  <material name="clearpath_light_grey">
    <color rgba="0.8 0.8 0.8 1.0"/>
  </material>
  <material name="clearpath_yellow">
    <color rgba="0.8 0.8 0.0 1.0"/>
  </material>
  <material name="clearpath_black">
    <color rgba="0.15 0.15 0.15 1.0"/>
  </material>
  <material name="clearpath_white">
    <color rgba="1.0 1.0 1.0 1.0"/>
  </material>
  <material name="clearpath_red">
    <color rgba="1.0 0.0 0.0 1.0"/>
  </material>
  <material name="clearpath_aluminum">
    <color rgba="0.5 0.5 0.5 1"/>
  </material>
  <material name="clearpath_plastic">
    <color rgba="0.1 0.1 0.1   1"/>
  </material>
  <!-- Chassis -->
  <link name="base_link"/>
  <joint name="base_link_joint" type="fixed">
    <origin rpy="3.1415 0 0" xyz="0 0 0"/>
    <parent link="base_link"/>
    <child link="chassis_link"/>
  </joint>
  <link name="chassis_link">
    <visual>
      <origin rpy="0 0 0" xyz="0 0 0"/>
      <geometry>
        <mesh filename="../meshes/body.stl"/>
      </geometry>
      <material name="clearpath_black"/>
    </visual>
    <collision>
      <origin xyz="0 0 0"/>
      <geometry>
        <mesh filename="../meshes/body-collision.stl"/>
      </geometry>
    </collision>
    <inertial>
      <origin rpy="1.5707963267948966 0 1.5707963267948966" xyz="0.012 0.002 0.067"/>
      <mass value="165.304"/>
      <inertia ixx="4.4744" ixy="0.03098" ixz="0.003647" iyy="7.1624" iyz="0.1228" izz="4.6155"/>
    </inertial>
  </link>
  <!-- Covers -->
  <joint name="right_side_cover_link_joint" type="fixed">
    <origin rpy="0 0 0" xyz="0 0 0"/>
    <parent link="chassis_link"/>
    <child link="right_side_cover_link"/>
  </joint>
  <joint name="left_side_cover_link_joint" type="fixed">
    <origin rpy="0 0 0" xyz="0 0 0"/>
    <parent link="chassis_link"/>
    <child link="left_side_cover_link"/>
  </joint>
  <link name="left_side_cover_link">
    <visual>
      <origin rpy="0 0 3.141592653589793" xyz="0 0 0"/>
      <geometry>
        <mesh filename="../meshes/side-cover.stl"/>
      </geometry>
      <material name="clearpath_yellow"/>
    </visual>
  </link>
  <link name="right_side_cover_link">
    <visual>
      <origin rpy="0 0 0" xyz="0 0 0"/>
      <geometry>
        <mesh filename="../meshes/side-cover.stl"/>
      </geometry>
      <material name="clearpath_yellow"/>
    </visual>
  </link>
  <joint name="front_cover_link_joint" type="fixed">
    <origin rpy="0 0 0" xyz="0 0 0"/>
    <parent link="chassis_link"/>
    <child link="front_cover_link"/>
  </joint>
  <link name="front_cover_link">
    <visual>
      <origin rpy="0 0 0" xyz="0 0 0"/>
      <geometry>
        <mesh filename="../meshes/end-cover.stl"/>
      </geometry>
      <material name="clearpath_black"/>
    </visual>
  </link>
  <joint name="rear_cover_link_joint" type="fixed">
    <origin rpy="0 0 0" xyz="0 0 0"/>
    <parent link="chassis_link"/>
    <child link="rear_cover_link"/>
  </joint>
  <link name="rear_cover_link">
    <visual>
      <origin rpy="0 0 3.141592653589793" xyz="0 0 0"/>
      <geometry>
        <mesh filename="../meshes/end-cover.stl"/>
      </geometry>
      <material name="clearpath_black"/>
    </visual>
  </link>
  <!-- Ligths -->
  <joint name="front_lights_link_joint" type="fixed">
    <origin rpy="0 0 0" xyz="0 0 0"/>
    <parent link="chassis_link"/>
    <child link="front_lights_link"/>
  </joint>
  <joint name="rear_lights_link_joint" type="fixed">
    <origin rpy="0 0 0" xyz="0 0 0"/>
    <parent link="chassis_link"/>
    <child link="rear_lights_link"/>
  </joint>
  <link name="front_lights_link">
    <visual>
      <origin rpy="0 0 0" xyz="0 0 0"/>
      <geometry>
        <mesh filename="../meshes/lights.stl"/>
      </geometry>
      <material name="clearpath_white"/>
    </visual>
  </link>
  <link name="rear_lights_link">
    <visual>
      <origin rpy="0 0 3.141592653589793" xyz="0 0 0"/>
      <geometry>
        <mesh filename="../meshes/lights.stl"/>
      </geometry>
      <material name="clearpath_red"/>
    </visual>
  </link>
  <!-- Axle -->
  <joint name="axle_joint" type="fixed">
    <origin rpy="0 0 0" xyz="0 0 0.05"/>
    <parent link="chassis_link"/>
    <child link="axle_link"/>
  </joint>
  <link name="axle_link">
    <visual>
      <origin rpy="0 1.5707963267948966 0" xyz="0 0 0"/>
      <geometry>
        <mesh filename="../meshes/axle.stl"/>
      </geometry>
      <material name="clearpath_black"/>
    </visual>
  </link>
  <!-- Riser -->
  <joint name="riser_link_joint" type="fixed">
    <origin rpy="0 0 0" xyz="0 0 0.22"/>
    <parent link="chassis_link"/>
    <child link="riser_link"/>
  </joint>
  <link name="riser_link">
    <visual>
      <origin rpy="0 0 0.7853981633974483" xyz="0 0 0.035"/>
      <geometry>
        <box size="0.493 0.493 0.07"/>
      </geometry>
      <material name="clearpath_light_grey"/>
    </visual>
    <collision>
      <origin rpy="0 0 0.7853981633974483" xyz="0 0 0.035"/>
      <geometry>
        <box size="0.493 0.493 0.07"/>
      </geometry>
    </collision>
  </link>
  <!-- Top Plate -->
  <joint name="top_link_joint" type="fixed">
    <origin rpy="0 0 0" xyz="0 0 -0.20500000000000002"/>
    <parent link="riser_link"/>
    <child link="top_link"/>
  </joint>
  <link name="top_link">
    <visual>
      <origin rpy="0 0 0" xyz="0 0 0"/>
      <geometry>
        <mesh filename="../meshes/top.stl"/>
      </geometry>
      <material name="clearpath_black"/>
    </visual>
    <collision>
      <origin rpy="0 0 0" xyz="0 0 0"/>
      <geometry>
        <mesh filename="../meshes/top.stl"/>
      </geometry>
    </collision>
  </link>
  <!-- Front Wheels -->
  <link name="front_rocker_link">
    <visual>
      <origin rpy="1.5707963267948966 0 1.5707963267948966" xyz="0 0 0"/>
      <geometry>
        <mesh filename="../meshes/rocker.stl"/>
      </geometry>
      <material name="clearpath_black"/>
    </visual>
    <inertial>
      <origin rpy="1.5707963267948966 0 1.5707963267948966" xyz="0 0 0"/>
      <mass value="10.267"/>
      <inertia ixx="0.0288" ixy="2.20484e-6" ixz="-1.3145e-5" iyy="0.4324" iyz="1.8944e-3" izz="0.4130"/>
    </inertial>
  </link>
  <joint name="front_rocker" type="fixed">
    <parent link="axle_link"/>
    <child link="front_rocker_link"/>
    <origin rpy="0 0 0" xyz="0.319 0 0"/>
    <axis xyz="1 0 0"/>
    <limit effort="0" lower="-0.08726" upper="0.08726" velocity="0"/>
  </joint>
  <link name="front_left_wheel_link">
    <visual>
      <origin rpy="1.5707963267948966 0 0" xyz="0 0 0"/>
      <geometry>
        <mesh filename="../meshes/mecanum.stl"/>
      </geometry>
      <material name="clearpath_black"/>
    </visual>
    <collision>
      <origin rpy="1.5707963267948966 0 0" xyz="0 0 0"/>
      <geometry>
        <cylinder length="0.079" radius="0.0759"/>
      </geometry>
    </collision>
    <inertial>
      <origin rpy="0 0 0" xyz="0 0 0"/>
      <mass value="2.5"/>
      <inertia ixx="0.0049007145833333335" ixy="0" ixz="0" iyy="0.0072010124999999986" iyz="0" izz="0.0049007145833333335"/>
    </inertial>
  </link>
  <gazebo>
    <plugin filename="libgz-sim-wheel-slip-system.so" name="gz::sim::systems::WheelSlip">
      <wheel link_name="front_left_wheel_link">
        <slip_compliance_lateral>1.0</slip_compliance_lateral>
        <slip_compliance_longitudinal>1.0</slip_compliance_longitudinal>
        <wheel_normal_force>200</wheel_normal_force>
        <wheel_radius>0.0759</wheel_radius>
      </wheel>
    </plugin>
  </gazebo>
  <gazebo reference="front_left_wheel_link">
    <collision>
      <surface>
        <friction>
          <ode>
            <mu>1.0</mu>
            <mu2>0.0</mu2>
            <fdir1 ignition:expressed_in="base_link">1 -1 0</fdir1>
          </ode>
        </friction>
      </surface>
    </collision>
  </gazebo>
  <joint name="front_left_wheel_joint" type="continuous">
    <parent link="front_rocker_link"/>
    <child link="front_left_wheel_link"/>
    <origin rpy="0 0 0" xyz="0 0.27549999999999997 0"/>
    <axis xyz="0 1 0"/>
  </joint>
  <link name="front_right_wheel_link">
    <visual>
      <origin rpy="1.5707963267948966 0 0" xyz="0 0 0"/>
      <geometry>
        <mesh filename="../meshes/mecanum.stl"/>
      </geometry>
      <material name="clearpath_black"/>
    </visual>
    <collision>
      <origin rpy="1.5707963267948966 0 0" xyz="0 0 0"/>
      <geometry>
        <cylinder length="0.079" radius="0.0759"/>
      </geometry>
    </collision>
    <inertial>
      <origin rpy="0 0 0" xyz="0 0 0"/>
      <mass value="2.5"/>
      <inertia ixx="0.0049007145833333335" ixy="0" ixz="0" iyy="0.0072010124999999986" iyz="0" izz="0.0049007145833333335"/>
    </inertial>
  </link>
  <gazebo>
    <plugin filename="libgz-sim-wheel-slip-system.so" name="gz::sim::systems::WheelSlip">
      <wheel link_name="front_right_wheel_link">
        <slip_compliance_lateral>1.0</slip_compliance_lateral>
        <slip_compliance_longitudinal>1.0</slip_compliance_longitudinal>
        <wheel_normal_force>200</wheel_normal_force>
        <wheel_radius>0.0759</wheel_radius>
      </wheel>
    </plugin>
  </gazebo>
  <gazebo reference="front_right_wheel_link">
    <collision>
      <surface>
        <friction>
          <ode>
            <mu>1.0</mu>
            <mu2>0.0</mu2>
            <fdir1 ignition:expressed_in="base_link">1 1 0</fdir1>
          </ode>
        </friction>
      </surface>
    </collision>
  </gazebo>
  <joint name="front_right_wheel_joint" type="continuous">
    <parent link="front_rocker_link"/>
    <child link="front_right_wheel_link"/>
    <origin rpy="0 0 0" xyz="0 -0.27549999999999997 0"/>
    <axis xyz="0 1 0"/>
  </joint>
  <!-- Rear Wheels -->
  <link name="rear_rocker_link">
    <visual>
      <origin rpy="1.5707963267948966 0 1.5707963267948966" xyz="0 0 0"/>
      <geometry>
        <mesh filename="../meshes/rocker.stl"/>
      </geometry>
      <material name="clearpath_black"/>
    </visual>
    <inertial>
      <origin rpy="1.5707963267948966 0 1.5707963267948966" xyz="0 0 0"/>
      <mass value="10.267"/>
      <inertia ixx="0.0288" ixy="2.20484e-6" ixz="-1.3145e-5" iyy="0.4324" iyz="1.8944e-3" izz="0.4130"/>
    </inertial>
  </link>
  <joint name="rear_rocker" type="fixed">
    <parent link="axle_link"/>
    <child link="rear_rocker_link"/>
    <origin rpy="0 0 0" xyz="-0.319 0 0"/>
    <axis xyz="1 0 0"/>
    <limit effort="0" velocity="0"/>
  </joint>
  <link name="rear_left_wheel_link">
    <visual>
      <origin rpy="1.5707963267948966 0 0" xyz="0 0 0"/>
      <geometry>
        <mesh filename="../meshes/mecanum.stl"/>
      </geometry>
      <material name="clearpath_black"/>
    </visual>
    <collision>
      <origin rpy="1.5707963267948966 0 0" xyz="0 0 0"/>
      <geometry>
        <cylinder length="0.079" radius="0.0759"/>
      </geometry>
    </collision>
    <inertial>
      <origin rpy="0 0 0" xyz="0 0 0"/>
      <mass value="2.5"/>
      <inertia ixx="0.0049007145833333335" ixy="0" ixz="0" iyy="0.0072010124999999986" iyz="0" izz="0.0049007145833333335"/>
    </inertial>
  </link>
  <gazebo>
    <plugin filename="libgz-sim-wheel-slip-system.so" name="gz::sim::systems::WheelSlip">
      <wheel link_name="rear_left_wheel_link">
        <slip_compliance_lateral>1.0</slip_compliance_lateral>
        <slip_compliance_longitudinal>1.0</slip_compliance_longitudinal>
        <wheel_normal_force>200</wheel_normal_force>
        <wheel_radius>0.0759</wheel_radius>
      </wheel>
    </plugin>
  </gazebo>
  <gazebo reference="rear_left_wheel_link">
    <collision>
      <surface>
        <friction>
          <ode>
            <mu>1.0</mu>
            <mu2>0.0</mu2>
            <fdir1 ignition:expressed_in="base_link">1 1 0</fdir1>
          </ode>
        </friction>
      </surface>
    </collision>
  </gazebo>
  <joint name="rear_left_wheel_joint" type="continuous">
    <parent link="rear_rocker_link"/>
    <child link="rear_left_wheel_link"/>
    <origin rpy="0 0 0" xyz="0 0.27549999999999997 0"/>
    <axis xyz="0 1 0"/>
  </joint>
  <link name="rear_right_wheel_link">
    <visual>
      <origin rpy="1.5707963267948966 0 0" xyz="0 0 0"/>
      <geometry>
        <mesh filename="../meshes/mecanum.stl"/>
      </geometry>
      <material name="clearpath_black"/>
    </visual>
    <collision>
      <origin rpy="1.5707963267948966 0 0" xyz="0 0 0"/>
      <geometry>
        <cylinder length="0.079" radius="0.0759"/>
      </geometry>
    </collision>
    <inertial>
      <origin rpy="0 0 0" xyz="0 0 0"/>
      <mass value="2.5"/>
      <inertia ixx="0.0049007145833333335" ixy="0" ixz="0" iyy="0.0072010124999999986" iyz="0" izz="0.0049007145833333335"/>
    </inertial>
  </link>
  <gazebo>
    <plugin filename="libgz-sim-wheel-slip-system.so" name="gz::sim::systems::WheelSlip">
      <wheel link_name="rear_right_wheel_link">
        <slip_compliance_lateral>1.0</slip_compliance_lateral>
        <slip_compliance_longitudinal>1.0</slip_compliance_longitudinal>
        <wheel_normal_force>200</wheel_normal_force>
        <wheel_radius>0.0759</wheel_radius>
      </wheel>
    </plugin>
  </gazebo>
  <gazebo reference="rear_right_wheel_link">
    <collision>
      <surface>
        <friction>
          <ode>
            <mu>1.0</mu>
            <mu2>0.0</mu2>
            <fdir1 ignition:expressed_in="base_link">1 -1 0</fdir1>
          </ode>
        </friction>
      </surface>
    </collision>
  </gazebo>
  <joint name="rear_right_wheel_joint" type="continuous">
    <parent link="rear_rocker_link"/>
    <child link="rear_right_wheel_link"/>
    <origin rpy="0 0 0" xyz="0 -0.27549999999999997 0"/>
    <axis xyz="0 1 0"/>
  </joint>
  <!-- ROS2 controls -->
  <ros2_control name="r100_hardware" type="system">
    <hardware>
      <plugin>clearpath_hardware_interfaces/PumaHardware</plugin>
    </hardware>
    <joint name="front_left_wheel_joint">
      <command_interface name="velocity"/>
      <state_interface name="position"/>
      <state_interface name="velocity"/>
    </joint>
    <joint name="front_right_wheel_joint">
      <command_interface name="velocity"/>
      <state_interface name="position"/>
      <state_interface name="velocity"/>
    </joint>
    <joint name="rear_left_wheel_joint">
      <command_interface name="velocity"/>
      <state_interface name="position"/>
      <state_interface name="velocity"/>
    </joint>
    <joint name="rear_right_wheel_joint">
      <command_interface name="velocity"/>
      <state_interface name="position"/>
      <state_interface name="velocity"/>
    </joint>
  </ros2_control>
  <!-- Internal IMU -->
  <link name="imu_0_link">
    <inertial>
      <mass value="0.001"/>
      <origin rpy="0 0 0" xyz="0 0 0"/>
      <inertia ixx="1e-09" ixy="0.0" ixz="0.0" iyy="1e-09" iyz="0.0" izz="1e-09"/>
    </inertial>
  </link>
  <joint name="imu_0_joint" type="fixed">
    <parent link="chassis_link"/>
    <child link="imu_0_link"/>
    <origin rpy="0 0 0" xyz="0.2085 -0.2902 0.1681"/>
  </joint>
  <gazebo reference="imu_0_link">
    <sensor name="imu_0" type="imu">
      <always_on>true</always_on>
      <update_rate>50</update_rate>
      <visualize>true</visualize>
      <gz_frame_id>imu_0_link</gz_frame_id>
    </sensor>
  </gazebo>
  <!-- Mounting Hardpoints -->
  <link name="default_mount"/>
  <joint name="default_mount_joint" type="fixed">
    <parent link="riser_link"/>
    <child link="default_mount"/>
    <origin rpy="0 0 0" xyz="0 0 0.07500000000000001"/>
  </joint>
  <!-- Attachments -->
  <!-- Links -->
  <link name="arm_mount_left_link"/>
  <joint name="arm_mount_left_joint" type="fixed">
    <parent link="arm_mount_bracket_link"/>
    <child link="arm_mount_left_link"/>
    <origin rpy="-0.7854 1.5708 0.0" xyz="0.14999 0.10483 -0.30903"/>
  </joint>
  <link name="arm_mount_right_link"/>
  <joint name="arm_mount_right_joint" type="fixed">
    <parent link="arm_mount_bracket_link"/>
    <child link="arm_mount_right_link"/>
    <origin rpy="0.7854 1.5708 0.0" xyz="0.14999 -0.10428 -0.30903"/>
  </joint>
  <link name="lidar3d_0_scan_link"/>
  <joint name="lidar3d_0_scan_joint" type="fixed">
    <parent link="lidar3d_0_sensor_link"/>
    <child link="lidar3d_0_scan_link"/>
    <origin rpy="0.0 0.0 3.1415" xyz="0.0 0.0 0.0"/>
  </joint>
  <link name="tripod_head_link">
    <visual>
      <geometry>
        <cylinder length="0.103" radius="0.02"/>
      </geometry>
      <material name="clearpath_dark_grey"/>
    </visual>
    <collision>
      <geometry>
        <cylinder length="0.103" radius="0.02"/>
      </geometry>
      <material name="clearpath_dark_grey"/>
    </collision>
  </link>
  <joint name="tripod_head_joint" type="fixed">
    <parent link="adapter_plate_link"/>
    <child link="tripod_head_link"/>
    <origin rpy="0.0 0.0 0.0" xyz="0.066 0.0 0.0642"/>
  </joint>
  <link name="enclosure_link">
    <visual>
      <geometry>
        <mesh filename="../meshes/enclosure.STL"/>
      </geometry>
      <material name="clearpath_dark_grey"/>
    </visual>
    <collision>
      <geometry>
        <mesh filename="../meshes/enclosure.STL"/>
      </geometry>
      <material name="clearpath_dark_grey"/>
    </collision>
  </link>
  <joint name="enclosure_joint" type="fixed">
    <parent link="default_mount"/>
    <child link="enclosure_link"/>
    <origin rpy="0.0 0.0 0.0" xyz="0.0 0.0 0.0"/>
  </joint>
  <link name="left_wifi_antenna_link">
    <visual>
      <geometry>
        <mesh filename="../meshes/wifi_antenna.STL"/>
      </geometry>
      <material name="clearpath_dark_grey"/>
    </visual>
    <collision>
      <geometry>
        <mesh filename="../meshes/wifi_antenna.STL"/>
      </geometry>
      <material name="clearpath_dark_grey"/>
    </collision>
  </link>
  <joint name="left_wifi_antenna_joint" type="fixed">
    <parent link="default_mount"/>
    <child link="left_wifi_antenna_link"/>
    <origin rpy="0.0 0.0 0.0" xyz="-0.16525 0.355 0.19795"/>
  </joint>
  <link name="right_wifi_antenna_link">
    <visual>
      <geometry>
        <mesh filename="../meshes/wifi_antenna.STL"/>
      </geometry>
      <material name="clearpath_dark_grey"/>
    </visual>
    <collision>
      <geometry>
        <mesh filename="../meshes/wifi_antenna.STL"/>
      </geometry>
      <material name="clearpath_dark_grey"/>
    </collision>
  </link>
  <joint name="right_wifi_antenna_joint" type="fixed">
    <parent link="default_mount"/>
    <child link="right_wifi_antenna_link"/>
    <origin rpy="0.0 0.0 0.0" xyz="-0.16525 -0.355 0.19795"/>
  </joint>
  <link name="autec_antenna_link">
    <visual>
      <geometry>
        <mesh filename="../meshes/autec_antenna.STL"/>
      </geometry>
      <material name="clearpath_dark_grey"/>
    </visual>
    <collision>
      <geometry>
        <mesh filename="../meshes/autec_antenna.STL"/>
      </geometry>
      <material name="clearpath_dark_grey"/>
    </collision>
  </link>
  <joint name="autec_antenna_joint" type="fixed">
    <parent link="default_mount"/>
    <child link="autec_antenna_link"/>
    <origin rpy="0.0 0.0 0.0" xyz="-0.0815 -0.355 0.19795"/>
  </joint>
  <link name="arm_mount_bracket_link">
    <visual>
      <geometry>
        <mesh filename="../meshes/arm_mount_bracket.STL"/>
      </geometry>
      <material name="clearpath_dark_grey"/>
    </visual>
    <collision>
      <geometry>
        <mesh filename="../meshes/arm_mount_bracket.STL"/>
      </geometry>
      <material name="clearpath_dark_grey"/>
    </collision>
  </link>
  <joint name="arm_mount_bracket_joint" type="fixed">
    <parent link="lift_0_mount"/>
    <child link="arm_mount_bracket_link"/>
    <origin rpy="0.0 0.0 0.0" xyz="0.0 0.0 0.0"/>
  </joint>
  <link name="adapter_plate_link">
    <visual>
      <geometry>
        <mesh filename="../meshes/adapter_plate.STL"/>
      </geometry>
      <material name="clearpath_dark_grey"/>
    </visual>
    <collision>
      <geometry>
        <mesh filename="../meshes/adapter_plate.STL"/>
      </geometry>
      <material name="clearpath_dark_grey"/>
    </collision>
  </link>
  <joint name="adapter_plate_joint" type="fixed">
    <parent link="lift_0_mount"/>
    <child link="adapter_plate_link"/>
    <origin rpy="0.0 0.0 0.0" xyz="0.0 0.0 0.0127"/>
  </joint>
  <link name="ouster_tower_link">
    <visual>
      <geometry>
        <mesh filename="../meshes/ouster_tower.STL"/>
      </geometry>
      <material name="clearpath_dark_grey"/>
    </visual>
    <collision>
      <geometry>
        <mesh filename="../meshes/ouster_tower.STL"/>
      </geometry>
      <material name="clearpath_dark_grey"/>
    </collision>
  </link>
  <joint name="ouster_tower_joint" type="fixed">
    <parent link="lift_0_mount"/>
    <child link="ouster_tower_link"/>
    <origin rpy="0.0 0.0 0.0" xyz="-0.019 0.0 0.0254"/>
  </joint>
  <!-- Mounts -->
  <!-- Sensors -->
  <link name="lidar2d_0_link">
    <visual>
      <origin rpy="0 0 0" xyz="0 0 0"/>
      <geometry>
        <!-- Origin of this mesh is the base of the bracket. -->
        <mesh filename="../meshes/hokuyo_ust.stl"/>
      </geometry>
      <material name="clearpath_dark_grey"/>
    </visual>
  </link>
  <link name="lidar2d_0_laser">
    <inertial>
      <mass value="1.1"/>
      <origin xyz="0 0 0"/>
      <inertia ixx="0.00307156543804" ixy="0.0" ixz="0.0" iyy="0.0031284904152700005" iyz="0.0" izz="0.00196432421427"/>
    </inertial>
  </link>
  <joint name="lidar2d_0_joint" type="fixed">
    <origin rpy="0.0 0.0 0.0" xyz="0.3922 0.0 0.1856"/>
    <parent link="chassis_link"/>
    <child link="lidar2d_0_link"/>
  </joint>
  <joint name="lidar2d_0_laser_joint" type="fixed">
    <!-- This offset is from the base of the bracket to the LIDAR's focal point. -->
    <origin rpy="0 0 0" xyz="0 0 0.0474"/>
    <parent link="lidar2d_0_link"/>
    <child link="lidar2d_0_laser"/>
  </joint>
  <gazebo reference="lidar2d_0_laser">
    <sensor name="lidar2d_0" type="gpu_lidar">
      <update_rate>40</update_rate>
      <visualize>true</visualize>
      <always_on>true</always_on>
      <gz_frame_id>lidar2d_0_laser</gz_frame_id>
      <topic>/sensors/lidar2d_0/scan</topic>
      <lidar>
        <scan>
          <horizontal>
            <samples>540</samples>
            <resolution>1</resolution>
            <min_angle>-2.356</min_angle>
            <max_angle>2.356</max_angle>
          </horizontal>
          <vertical>
            <samples>1</samples>
            <resolution>1</resolution>
            <min_angle>0</min_angle>
            <max_angle>0</max_angle>
          </vertical>
        </scan>
        <range>
          <min>0.05</min>
          <max>25.0</max>
          <resolution>0.01</resolution>
        </range>
      </lidar>
    </sensor>
  </gazebo>
  <link name="lidar2d_1_link">
    <visual>
      <origin rpy="0 0 0" xyz="0 0 0"/>
      <geometry>
        <!-- Origin of this mesh is the base of the bracket. -->
        <mesh filename="../meshes/hokuyo_ust.stl"/>
      </geometry>
      <material name="clearpath_dark_grey"/>
    </visual>
  </link>
  <link name="lidar2d_1_laser">
    <inertial>
      <mass value="1.1"/>
      <origin xyz="0 0 0"/>
      <inertia ixx="0.00307156543804" ixy="0.0" ixz="0.0" iyy="0.0031284904152700005" iyz="0.0" izz="0.00196432421427"/>
    </inertial>
  </link>
  <joint name="lidar2d_1_joint" type="fixed">
    <origin rpy="0.0 0.0 3.14159" xyz="-0.3922 0.0 0.1856"/>
    <parent link="chassis_link"/>
    <child link="lidar2d_1_link"/>
  </joint>
  <joint name="lidar2d_1_laser_joint" type="fixed">
    <!-- This offset is from the base of the bracket to the LIDAR's focal point. -->
    <origin rpy="0 0 0" xyz="0 0 0.0474"/>
    <parent link="lidar2d_1_link"/>
    <child link="lidar2d_1_laser"/>
  </joint>
  <gazebo reference="lidar2d_1_laser">
    <sensor name="lidar2d_1" type="gpu_lidar">
      <update_rate>40</update_rate>
      <visualize>true</visualize>
      <always_on>true</always_on>
      <gz_frame_id>lidar2d_1_laser</gz_frame_id>
      <topic>/sensors/lidar2d_1/scan</topic>
      <lidar>
        <scan>
          <horizontal>
            <samples>540</samples>
            <resolution>1</resolution>
            <min_angle>-2.356</min_angle>
            <max_angle>2.356</max_angle>
          </horizontal>
          <vertical>
            <samples>1</samples>
            <resolution>1</resolution>
            <min_angle>0</min_angle>
            <max_angle>0</max_angle>
          </vertical>
        </scan>
        <range>
          <min>0.05</min>
          <max>25.0</max>
          <resolution>0.01</resolution>
        </range>
      </lidar>
    </sensor>
  </gazebo>
  <link name="lidar3d_0_base_link"/>
  <!-- Lidar Link -->
  <link name="lidar3d_0_link">
    <inertial>
      <mass value="0.41"/>
      <origin xyz="0 0 0.029175"/>
      <inertia ixx="0.00031028364375" ixy="0" ixz="0" iyy="0.00031028364375" iyz="0" izz="0.00038791124999999993"/>
    </inertial>
    <visual>
      <material name="ouster_grey">
        <color rgba="0.8 0.8 0.8 1.0"/>
      </material>
      <origin xyz="0 0 0"/>
      <geometry>
        <mesh filename="../meshes/os1_lidar.stl"/>
      </geometry>
    </visual>
    <collision>
      <material>
        <color rgba="0.8 0.8 0.8 1.0"/>
      </material>
      <origin rpy="0 0 0" xyz="0 0 0.029175"/>
      <geometry>
        <cylinder length="0.05835" radius="0.0435"/>
      </geometry>
    </collision>
  </link>
  <link name="lidar3d_0_cap_link">
    <inertial>
      <mass value="0.079"/>
      <origin xyz="0 0 0.011"/>
      <inertia ixx="3.544144391927083e-05" ixy="0" ixz="0" iyy="3.544144391927083e-05" iyz="0" izz="6.4510221171875e-05"/>
    </inertial>
    <visual>
      <material name="ouster_grey">
        <color rgba="0.8 0.8 0.8 1.0"/>
      </material>
      <origin xyz="0 0 -0.05835"/>
      <geometry>
        <mesh filename="../meshes/os1_fins.stl"/>
      </geometry>
    </visual>
    <collision>
      <material>
        <color rgba="0.8 0.8 0.8 1.0"/>
      </material>
      <origin rpy="0 0 0" xyz="0 0 0.011"/>
      <geometry>
        <cylinder length="0.022" radius="0.0404125"/>
      </geometry>
    </collision>
  </link>
  <!-- Base Joint -->
  <joint name="lidar3d_0_base_joint" type="fixed">
    <child link="lidar3d_0_base_link"/>
    <parent link="ouster_tower_link"/>
    <origin rpy="0.0 0.0 0.0" xyz="0.0 0.0 0.14318"/>
  </joint>
  <!-- Lidar Joint -->
  <joint name="lidar3d_0_joint" type="fixed">
    <child link="lidar3d_0_link"/>
    <parent link="lidar3d_0_base_link"/>
    <origin xyz="0 0 0.0"/>
  </joint>
  <!-- Thermal Cap Joint -->
  <joint name="{name}_cap_joint" type="fixed">
    <child link="lidar3d_0_cap_link"/>
    <parent link="lidar3d_0_link"/>
    <origin xyz="0 0 0.05835"/>
  </joint>
  <!-- Sensor Joint -->
  <link name="lidar3d_0_sensor_link"/>
  <joint name="lidar3d_0_sensor_joint" type="fixed">
    <child link="lidar3d_0_sensor_link"/>
    <parent link="lidar3d_0_link"/>
    <origin xyz="0 0 0.038195"/>
  </joint>
  <!-- Gazebo -->
  <gazebo reference="lidar3d_0_sensor_link">
    <sensor name="lidar3d_0" type="gpu_lidar">
      <update_rate>20</update_rate>
      <visualize>true</visualize>
      <always_on>true</always_on>
      <ignition_frame_id>lidar3d_0_sensor_link</ignition_frame_id>
      <topic>/sensors/lidar3d_0/scan</topic>
      <lidar>
        <scan>
          <horizontal>
            <samples>1024</samples>
            <resolution>1</resolution>
            <min_angle>-3.141592</min_angle>
            <max_angle>3.141592</max_angle>
          </horizontal>
          <vertical>
            <samples>64</samples>
            <resolution>1</resolution>
            <min_angle>-0.261799</min_angle>
            <max_angle>0.261799</max_angle>
          </vertical>
        </scan>
        <range>
          <min>0.9</min>
          <max>130.0</max>
          <resolution>0.01</resolution>
        </range>
      </lidar>
    </sensor>
  </gazebo>
  <!-- camera body, with origin at bottom screw mount -->
  <joint name="camera_0_joint" type="fixed">
    <origin rpy="0.0 0.0 0.0" xyz="0.0 0.0 0.0515"/>
    <parent link="tripod_head_link"/>
    <child link="camera_0_bottom_screw_frame"/>
  </joint>
  <link name="camera_0_bottom_screw_frame"/>
  <joint name="camera_0_link_joint" type="fixed">
    <origin rpy="0 0 0" xyz="0.010600000000000002 0.0175 0.0125"/>
    <parent link="camera_0_bottom_screw_frame"/>
    <child link="camera_0_link"/>
  </joint>
  <link name="camera_0_link">
    <visual>
      <!-- the mesh origin is at front plate in between the two infrared camera axes -->
      <origin rpy="1.5707963267948966 0 1.5707963267948966" xyz="0.0043 -0.0175 0"/>
      <geometry>
        <mesh filename="../meshes/d435.stl"/>
      </geometry>
    </visual>
    <collision>
      <origin rpy="0 0 0" xyz="0 -0.0175 0"/>
      <geometry>
        <box size="0.02505 0.09 0.025"/>
      </geometry>
    </collision>
    <inertial>
      <!-- The following are not reliable values, and should not be used for modeling -->
      <mass value="0.072"/>
      <origin xyz="0 0 0"/>
      <inertia ixx="0.003881243" ixy="0.0" ixz="0.0" iyy="0.000498940" iyz="0.0" izz="0.003879257"/>
    </inertial>
  </link>
  <gazebo reference="camera_0_link">
    <sensor name="camera_0" type="rgbd_camera">
      <camera>
        <horizontal_fov>1.25</horizontal_fov>
        <image>
          <width>640</width>
          <height>480</height>
        </image>
        <clip>
          <near>0.3</near>
          <far>100</far>
        </clip>
        <gz_frame_id>camera_0_link</gz_frame_id>
        <optical_frame_id>camera_0_color_optical_frame</optical_frame_id>
      </camera>
      <always_on>1</always_on>
      <update_rate>30</update_rate>
      <visualize>true</visualize>
      <gz_frame_id>camera_0_link</gz_frame_id>
      <topic>/sensors/camera_0</topic>
    </sensor>
  </gazebo>
  <link name="imu_1_base_link"/>
  <link name="imu_1_link">
    <visual>
      <geometry>
        <box size="0.02 0.02 0.005"/>
      </geometry>
      <material name="clearpath_dark_grey"/>
    </visual>
  </link>
  <joint name="imu_1_base_joint" type="fixed">
    <origin rpy="0.0 0.0 3.14" xyz="0.0 -0.136 0.0"/>
    <parent link="default_mount"/>
    <child link="imu_1_base_link"/>
  </joint>
  <joint name="imu_1_joint" type="fixed">
    <origin xyz="0 0 0.0025"/>
    <parent link="imu_1_base_link"/>
    <child link="imu_1_link"/>
  </joint>
  <gazebo reference="imu_1_link">
    <sensor name="imu_1" type="imu">
      <always_on>true</always_on>
      <update_rate>100</update_rate>
      <visualize>true</visualize>
      <gz_frame_id>imu_1_link</gz_frame_id>
      <topic>/sensors/imu_1/data</topic>
    </sensor>
  </gazebo>
  <!-- Manipulators -->
  <!-- Link -->
  <link name="lift_0_plate_link">
    <visual>
      <origin rpy="0.0 0.0 0.0" xyz="0.0 0.0 0.0"/>
      <geometry>
        <mesh filename="../meshes/plate.stl"/>
      </geometry>
      <material name="LightGrey">
        <color rgba="0.7 0.7 0.7 1.0"/>
      </material>
    </visual>
    <collision>
      <origin rpy="0.0 0.0 0.0" xyz="0.0 0.0 0.01"/>
      <geometry>
        <box size="0.2 0.2 0.02"/>
      </geometry>
      <material name="LightGrey">
        <color rgba="0.7 0.7 0.7 1.0"/>
      </material>
    </collision>
    <inertial>
      <mass value="1.0"/>
      <origin rpy="0.0 0.0 0.0" xyz="0.0 0.0 0.01"/>
      <inertia ixx="0.003366666666666667" ixy="0.0" ixz="0.0" iyy="0.003366666666666667" iyz="0.0" izz="0.006666666666666668"/>
    </inertial>
  </link>
  <joint name="lift_0_plate_joint" type="fixed">
    <child link="lift_0_plate_link"/>
    <parent link="default_mount"/>
    <origin rpy="0.0 0.0 0.0" xyz="-0.0815 0.0 0.0"/>
  </joint>
  <joint name="lift_0_base_joint" type="fixed">
    <child link="lift_0_base_link"/>
    <parent link="lift_0_plate_link"/>
    <origin rpy="0.0 0.0 0.0" xyz="0.0 0.0 0.018000000000000002"/>
  </joint>
  <!-- Link -->
  <link name="lift_0_base_link">
    <visual>
      <origin rpy="0.0 0.0 0.0" xyz="0.0 0.0 -0.0179"/>
      <geometry>
        <mesh filename="../meshes/base.stl"/>
      </geometry>
      <material name="LightGrey">
        <color rgba="0.7 0.7 0.7 1.0"/>
      </material>
    </visual>
    <collision>
      <origin rpy="0.0 0.0 0.0" xyz="0.0 0.0 0.41035"/>
      <geometry>
        <box size="0.1644 0.1644 0.8207"/>
      </geometry>
      <material name="LightGrey">
        <color rgba="0.7 0.7 0.7 1.0"/>
      </material>
    </collision>
    <inertial>
      <mass value="10.0"/>
      <origin rpy="0.0 0.0 0.0" xyz="0.0 0.0 0.41035"/>
      <inertia ixx="0.5838132083333333" ixy="0.0" ixz="0.0" iyy="0.5838132083333333" iyz="0.0" izz="0.0450456"/>
    </inertial>
  </link>
  <!-- Link -->
  <link name="lift_0_lower_link">
    <visual>
      <origin rpy="0.0 0.0 0.0" xyz="0.0 0.0 -0.467"/>
      <geometry>
        <mesh filename="../meshes/lower.stl"/>
      </geometry>
      <material name="LightGrey">
        <color rgba="0.7 0.7 0.7 1.0"/>
      </material>
    </visual>
    <collision>
      <origin rpy="0.0 0.0 0.0" xyz="0.0 0.0 0.3999999999999999"/>
      <geometry>
        <box size="0.15639999999999998 0.15610000000000002 0.7999999999999998"/>
      </geometry>
      <material name="LightGrey">
        <color rgba="0.7 0.7 0.7 1.0"/>
      </material>
    </collision>
    <inertial>
      <mass value="10.0"/>
      <origin rpy="0.0 0.0 0.0" xyz="0.0 0.0 0.3999999999999999"/>
      <inertia ixx="0.5536393416666664" ixy="0.0" ixz="0.0" iyy="0.5537174666666664" iyz="0.0" izz="0.040690141666666665"/>
    </inertial>
  </link>
  <joint name="lift_0_lower_joint" type="prismatic">
    <child link="lift_0_lower_link"/>
    <parent link="lift_0_base_link"/>
    <origin rpy="0.0 0.0 0.0" xyz="0.0 0.0 0.027"/>
    <limit effort="2000" lower="0.0" upper="0.4" velocity="0.088"/>
    <axis xyz="0 0 1"/>
    <dynamics damping="0.01" friction="0.01"/>
  </joint>
  <!-- Link -->
  <link name="lift_0_upper_link">
    <visual>
      <origin rpy="0.0 0.0 0.0" xyz="0.0 0.0 -0.847"/>
      <geometry>
        <mesh filename="../meshes/upper.stl"/>
      </geometry>
      <material name="LightGrey">
        <color rgba="0.7 0.7 0.7 1.0"/>
      </material>
    </visual>
    <collision>
      <origin rpy="0.0 0.0 0.0" xyz="0.0 0.0 0.41900000000000004"/>
      <geometry>
        <box size="0.129 0.129 0.8380000000000001"/>
      </geometry>
      <material name="LightGrey">
        <color rgba="0.7 0.7 0.7 1.0"/>
      </material>
    </collision>
    <inertial>
      <mass value="10.0"/>
      <origin rpy="0.0 0.0 0.0" xyz="0.0 0.0 0.41900000000000004"/>
      <inertia ixx="0.5990708333333334" ixy="0.0" ixz="0.0" iyy="0.5990708333333334" iyz="0.0" izz="0.027735"/>
    </inertial>
  </link>
  <joint name="lift_0_upper_joint" type="prismatic">
    <child link="lift_0_upper_link"/>
    <parent link="lift_0_lower_link"/>
    <origin rpy="0.0 0.0 0.0" xyz="0.0 0.0 0.007"/>
    <axis xyz="0 0 1"/>
    <limit effort="2000" lower="0.0" upper="0.4" velocity="0.088"/>
    <dynamics damping="0.01" friction="0.01"/>
    <mimic joint="lift_0_lower_joint"/>
  </joint>
  <!-- Link -->
  <link name="lift_0_mount_link">
    <visual>
      <origin rpy="0.0 0.0 0.0" xyz="0.0 0.0 -1.69"/>
      <geometry>
        <mesh filename="../meshes/mount.stl"/>
      </geometry>
      <material name="LightGrey">
        <color rgba="0.7 0.7 0.7 1.0"/>
      </material>
    </visual>
    <collision>
      <origin rpy="0.0 0.0 0.0" xyz="0.0 0.0 0.007500000000000062"/>
      <geometry>
        <box size="0.251 0.251 0.015000000000000124"/>
      </geometry>
      <material name="LightGrey">
        <color rgba="0.7 0.7 0.7 1.0"/>
      </material>
    </collision>
    <inertial>
      <mass value="2.0"/>
      <origin rpy="0.0 0.0 0.0" xyz="0.0 0.0 0.007500000000000062"/>
      <inertia ixx="0.010537666666666667" ixy="0.0" ixz="0.0" iyy="0.010537666666666667" iyz="0.0" izz="0.021000333333333333"/>
    </inertial>
  </link>
  <joint name="lift_0__mount_link_joint" type="fixed">
    <child link="lift_0_mount_link"/>
    <parent link="lift_0_upper_link"/>
    <origin rpy="0.0 0.0 0.0" xyz="0.0 0.0 0.8380000000000001"/>
  </joint>
  <link name="lift_0_mount"/>
  <joint name="lift_0_mount_joint" type="fixed">
    <child link="lift_0_mount"/>
    <parent link="lift_0_mount_link"/>
    <origin rpy="0.0 0.0 0.0" xyz="0.0 0.0 0.015000000000000124"/>
  </joint>
  <!-- Extras -->
  <!-- Parent Joint -->
  <joint name="arm_0_fr3_joint0" type="fixed">
    <child link="arm_0_fr3_link0"/>
    <parent link="arm_mount_left_link"/>
    <origin rpy="0.0 0.0 0.7854" xyz="0.0 0.0 0.0"/>
  </joint>
  <!-- safety_distance: Minimum safety distance in [m] by which the collision volumes are expanded and which is enforced during robot motions -->
  <!-- arm_id: Namespace of the robot arm. Serves to differentiate between arms in case of multiple instances. -->
  <!-- joint_limits: description of the joint limits that comes from a YAML file. Example definition: ${xacro.load_yaml('$(find franka_description)/robots/fr3/joint_limits.yaml')} -->
  <!-- kinematics: description of the kinematics that comes from a YAML file. Example definition: ${xacro.load_yaml('$(find franka_description)/robots/fr3/kinematics.yaml')} -->
  <!-- inertials: description of the inertials that comes from a YAML file. Example definition: ${xacro.load_yaml('$(find franka_description)/robots/fr3/inertials.yaml')} -->
  <!-- dynamics: description of the dynamics that comes from a YAML file. Example definition: ${xacro.load_yaml('$(find franka_description)/robots/fr3/dynamics.yaml')} -->
  <!-- sub-link defining detailed meshes for collision with environment -->
  <link name="arm_0_fr3_link0">
    <visual name="arm_0_fr3_link0_visual">
      <geometry>
        <mesh filename="../meshes/link0.stl"/>
      </geometry>
    </visual>
    <collision name="arm_0_fr3_link0_collision">
      <geometry>
        <mesh filename="../meshes/link0.stl"/>
      </geometry>
    </collision>
    <inertial>
      <origin rpy="0 0 0" xyz="-0.0172 0.0004 0.0745"/>
      <mass value="2.3966"/>
      <inertia ixx="0.009" ixy="0.0" ixz="0.002" iyy="0.0115" iyz="0.0" izz="0.0085"/>
    </inertial>
  </link>
  <!-- sub-link defining detailed meshes for collision with environment -->
  <link name="arm_0_fr3_link1">
    <visual name="arm_0_fr3_link1_visual">
      <geometry>
        <mesh filename="../meshes/link1.stl"/>
      </geometry>
    </visual>
    <collision name="arm_0_fr3_link1_collision">
      <geometry>
        <mesh filename="../meshes/link1.stl"/>
      </geometry>
    </collision>
    <inertial>
      <origin rpy="0 0 0" xyz="0.0000004128 -0.0181251324 -0.0386035970"/>
      <mass value="2.9274653454"/>
      <inertia ixx="0.023927316485107913" ixy="1.3317903455714081e-05" ixz="-0.00011404774918616684" iyy="0.0224821613275756" iyz="-0.0019950320628240115" izz="0.006350098258530016"/>
    </inertial>
  </link>
  <joint name="arm_0_fr3_joint1" type="revolute">
    <origin rpy="0 0 0" xyz="0 0 0.333"/>
    <parent link="arm_0_fr3_link0"/>
    <child link="arm_0_fr3_link1"/>
    <axis xyz="0 0 1"/>
    <limit effort="87.0" lower="-2.7437" upper="2.7437" velocity="2.62"/>
    <safety_controller k_position="100.0" k_velocity="40.0" soft_lower_limit="-2.7437" soft_upper_limit="2.7437"/>
    <dynamics D="1" K="7000" damping="0.003" friction="0.2" mu_coulomb="0" mu_viscous="16"/>
  </joint>
  <!-- sub-link defining detailed meshes for collision with environment -->
  <link name="arm_0_fr3_link2">
    <visual name="arm_0_fr3_link2_visual">
      <geometry>
        <mesh filename="../meshes/link2.stl"/>
      </geometry>
    </visual>
    <collision name="arm_0_fr3_link2_collision">
      <geometry>
        <mesh filename="../meshes/link2.stl"/>
      </geometry>
    </collision>
    <inertial>
      <origin rpy="0 0 0" xyz="0.0031828864 -0.0743221644 0.0088146084"/>
      <mass value="2.9355370338"/>
      <inertia ixx="0.041938946257609425" ixy="0.00020257331521090626" ixz="0.004077784227179924" iyy="0.02514514885014724" iyz="-0.0042252158006570156" izz="0.06170214472888839"/>
    </inertial>
  </link>
  <joint name="arm_0_fr3_joint2" type="revolute">
    <origin rpy="-1.570796326794897 0 0" xyz="0 0 0"/>
    <parent link="arm_0_fr3_link1"/>
    <child link="arm_0_fr3_link2"/>
    <axis xyz="0 0 1"/>
    <limit effort="87.0" lower="-1.7837" upper="1.7837" velocity="2.62"/>
    <safety_controller k_position="100.0" k_velocity="40.0" soft_lower_limit="-1.7837" soft_upper_limit="1.7837"/>
    <dynamics D="1" K="7000" damping="0.003" friction="0.2" mu_coulomb="0" mu_viscous="16"/>
  </joint>
  <!-- sub-link defining detailed meshes for collision with environment -->
  <link name="arm_0_fr3_link3">
    <visual name="arm_0_fr3_link3_visual">
      <geometry>
        <mesh filename="../meshes/link3.stl"/>
      </geometry>
    </visual>
    <collision name="arm_0_fr3_link3_collision">
      <geometry>
        <mesh filename="../meshes/link3.stl"/>
      </geometry>
    </collision>
    <inertial>
      <origin rpy="0 0 0" xyz="0.0407015686 -0.0048200565 -0.0289730823"/>
      <mass value="2.2449013699"/>
      <inertia ixx="0.02410142547240885" ixy="0.002404694559042109" ixz="-0.002856269270114313" iyy="0.01974053266708178" iyz="-0.002104212683891874" izz="0.019044494482244823"/>
    </inertial>
  </link>
  <joint name="arm_0_fr3_joint3" type="revolute">
    <origin rpy="1.570796326794897 0 0" xyz="0 -0.316 0"/>
    <parent link="arm_0_fr3_link2"/>
    <child link="arm_0_fr3_link3"/>
    <axis xyz="0 0 1"/>
    <limit effort="87.0" lower="-2.9007" upper="2.9007" velocity="2.62"/>
    <safety_controller k_position="100.0" k_velocity="40.0" soft_lower_limit="-2.9007" soft_upper_limit="2.9007"/>
    <dynamics D="1" K="7000" damping="0.003" friction="0.2" mu_coulomb="0" mu_viscous="16"/>
  </joint>
  <!-- sub-link defining detailed meshes for collision with environment -->
  <link name="arm_0_fr3_link4">
    <visual name="arm_0_fr3_link4_visual">
      <geometry>
        <mesh filename="../meshes/link4.stl"/>
      </geometry>
    </visual>
    <collision name="arm_0_fr3_link4_collision">
      <geometry>
        <mesh filename="../meshes/link4.stl"/>
      </geometry>
    </collision>
    <inertial>
      <origin rpy="0 0 0" xyz="-0.0459100965 0.0630492960 -0.0085187868"/>
      <mass value="2.6155955791"/>
      <inertia ixx="0.03452998321913202" ixy="0.01322552265982813" ixz="0.01015142998484113" iyy="0.028881621933049058" iyz="-0.0009762833870704552" izz="0.04125471171146641"/>
    </inertial>
  </link>
  <joint name="arm_0_fr3_joint4" type="revolute">
    <origin rpy="1.570796326794897 0 0" xyz="0.0825 0 0"/>
    <parent link="arm_0_fr3_link3"/>
    <child link="arm_0_fr3_link4"/>
    <axis xyz="0 0 1"/>
    <limit effort="87.0" lower="-3.0421" upper="-0.1518" velocity="2.62"/>
    <safety_controller k_position="100.0" k_velocity="40.0" soft_lower_limit="-3.0421" soft_upper_limit="-0.1518"/>
    <dynamics D="1" K="7000" damping="0.003" friction="0.2" mu_coulomb="0" mu_viscous="16"/>
  </joint>
  <!-- sub-link defining detailed meshes for collision with environment -->
  <link name="arm_0_fr3_link5">
    <visual name="arm_0_fr3_link5_visual">
      <geometry>
        <mesh filename="../meshes/link5.stl"/>
      </geometry>
    </visual>
    <collision name="arm_0_fr3_link5_collision">
      <geometry>
        <mesh filename="../meshes/link5.stl"/>
      </geometry>
    </collision>
    <inertial>
      <origin rpy="0 0 0" xyz="-0.0016039605 0.0292536262 -0.0972965990"/>
      <mass value="2.3271207594"/>
      <inertia ixx="0.051610278463662895" ixy="-0.005715173387783472" ixz="-0.0035673167625872135" iyy="0.04787729713371481" iyz="0.010673985108535986" izz="0.016423625579357254"/>
    </inertial>
  </link>
  <joint name="arm_0_fr3_joint5" type="revolute">
    <origin rpy="-1.570796326794897 0 0" xyz="-0.0825 0.384 0"/>
    <parent link="arm_0_fr3_link4"/>
    <child link="arm_0_fr3_link5"/>
    <axis xyz="0 0 1"/>
    <limit effort="12.0" lower="-2.8065" upper="2.8065" velocity="5.26"/>
    <safety_controller k_position="100.0" k_velocity="40.0" soft_lower_limit="-2.8065" soft_upper_limit="2.8065"/>
    <dynamics D="1" K="7000" damping="0.003" friction="0.2" mu_coulomb="0" mu_viscous="16"/>
  </joint>
  <!-- sub-link defining detailed meshes for collision with environment -->
  <link name="arm_0_fr3_link6">
    <visual name="arm_0_fr3_link6_visual">
      <geometry>
        <mesh filename="../meshes/link6.stl"/>
      </geometry>
    </visual>
    <collision name="arm_0_fr3_link6_collision">
      <geometry>
        <mesh filename="../meshes/link6.stl"/>
      </geometry>
    </collision>
    <inertial>
      <origin rpy="0 0 0" xyz="0.0597131221 -0.0410294666 -0.0101692726"/>
      <mass value="1.8170376524"/>
      <inertia ixx="0.005412333594383447" ixy="0.006193456360285834" ixz="0.0014219289306117652" iyy="0.014058329545509979" iyz="-0.0013140753741120031" izz="0.016080817924212554"/>
    </inertial>
  </link>
  <joint name="arm_0_fr3_joint6" type="revolute">
    <origin rpy="1.570796326794897 0 0" xyz="0 0 0"/>
    <parent link="arm_0_fr3_link5"/>
    <child link="arm_0_fr3_link6"/>
    <axis xyz="0 0 1"/>
    <limit effort="12.0" lower="0.5445" upper="4.5169" velocity="4.18"/>
    <safety_controller k_position="100.0" k_velocity="40.0" soft_lower_limit="0.5445" soft_upper_limit="4.5169"/>
    <dynamics D="1" K="7000" damping="0.003" friction="0.2" mu_coulomb="0" mu_viscous="16"/>
  </joint>
  <!-- sub-link defining detailed meshes for collision with environment -->
  <link name="arm_0_fr3_link7">
    <visual name="arm_0_fr3_link7_visual">
      <geometry>
        <mesh filename="../meshes/link7.stl"/>
      </geometry>
    </visual>
    <collision name="arm_0_fr3_link7_collision">
      <geometry>
        <mesh filename="../meshes/link7.stl"/>
      </geometry>
    </collision>
    <inertial>
      <origin rpy="0 0 0" xyz="0.0045225817 0.0086261921 -0.0161633251"/>
      <mass value="0.6271432862"/>
      <inertia ixx="0.00021092389150104718" ixy="-2.433299114461931e-05" ixz="4.564480393778983e-05" iyy="0.00017718568002411474" iyz="8.744070223226438e-05" izz="5.993190599659971e-05"/>
    </inertial>
  </link>
  <joint name="arm_0_fr3_joint7" type="revolute">
    <origin rpy="1.570796326794897 0 0" xyz="0.088 0 0"/>
    <parent link="arm_0_fr3_link6"/>
    <child link="arm_0_fr3_link7"/>
    <axis xyz="0 0 1"/>
    <limit effort="12.0" lower="-3.0159" upper="3.0159" velocity="5.26"/>
    <safety_controller k_position="100.0" k_velocity="40.0" soft_lower_limit="-3.0159" soft_upper_limit="3.0159"/>
    <dynamics D="1" K="7000" damping="0.003" friction="0.2" mu_coulomb="0" mu_viscous="16"/>
  </joint>
  <link name="arm_0_fr3_link8"/>
  <joint name="arm_0_fr3_joint8" type="fixed">
    <origin rpy="0 0 0" xyz="0 0 0.107"/>
    <parent link="arm_0_fr3_link7"/>
    <child link="arm_0_fr3_link8"/>
  </joint>
  <!-- Parent Joint -->
  <joint name="arm_1_fr3_joint0" type="fixed">
    <child link="arm_1_fr3_link0"/>
    <parent link="arm_mount_right_link"/>
    <origin rpy="0.0 0.0 -0.7854" xyz="0.0 0.0 0.0"/>
  </joint>
  <!-- safety_distance: Minimum safety distance in [m] by which the collision volumes are expanded and which is enforced during robot motions -->
  <!-- arm_id: Namespace of the robot arm. Serves to differentiate between arms in case of multiple instances. -->
  <!-- joint_limits: description of the joint limits that comes from a YAML file. Example definition: ${xacro.load_yaml('$(find franka_description)/robots/fr3/joint_limits.yaml')} -->
  <!-- kinematics: description of the kinematics that comes from a YAML file. Example definition: ${xacro.load_yaml('$(find franka_description)/robots/fr3/kinematics.yaml')} -->
  <!-- inertials: description of the inertials that comes from a YAML file. Example definition: ${xacro.load_yaml('$(find franka_description)/robots/fr3/inertials.yaml')} -->
  <!-- dynamics: description of the dynamics that comes from a YAML file. Example definition: ${xacro.load_yaml('$(find franka_description)/robots/fr3/dynamics.yaml')} -->
  <!-- sub-link defining detailed meshes for collision with environment -->
  <link name="arm_1_fr3_link0">
    <visual name="arm_1_fr3_link0_visual">
      <geometry>
        <mesh filename="../meshes/link0.stl"/>
      </geometry>
    </visual>
    <collision name="arm_1_fr3_link0_collision">
      <geometry>
        <mesh filename="../meshes/link0.stl"/>
      </geometry>
    </collision>
    <inertial>
      <origin rpy="0 0 0" xyz="-0.0172 0.0004 0.0745"/>
      <mass value="2.3966"/>
      <inertia ixx="0.009" ixy="0.0" ixz="0.002" iyy="0.0115" iyz="0.0" izz="0.0085"/>
    </inertial>
  </link>
  <!-- sub-link defining detailed meshes for collision with environment -->
  <link name="arm_1_fr3_link1">
    <visual name="arm_1_fr3_link1_visual">
      <geometry>
        <mesh filename="../meshes/link1.stl"/>
      </geometry>
    </visual>
    <collision name="arm_1_fr3_link1_collision">
      <geometry>
        <mesh filename="../meshes/link1.stl"/>
      </geometry>
    </collision>
    <inertial>
      <origin rpy="0 0 0" xyz="0.0000004128 -0.0181251324 -0.0386035970"/>
      <mass value="2.9274653454"/>
      <inertia ixx="0.023927316485107913" ixy="1.3317903455714081e-05" ixz="-0.00011404774918616684" iyy="0.0224821613275756" iyz="-0.0019950320628240115" izz="0.006350098258530016"/>
    </inertial>
  </link>
  <joint name="arm_1_fr3_joint1" type="revolute">
    <origin rpy="0 0 0" xyz="0 0 0.333"/>
    <parent link="arm_1_fr3_link0"/>
    <child link="arm_1_fr3_link1"/>
    <axis xyz="0 0 1"/>
    <limit effort="87.0" lower="-2.7437" upper="2.7437" velocity="2.62"/>
    <safety_controller k_position="100.0" k_velocity="40.0" soft_lower_limit="-2.7437" soft_upper_limit="2.7437"/>
    <dynamics D="1" K="7000" damping="0.003" friction="0.2" mu_coulomb="0" mu_viscous="16"/>
  </joint>
  <!-- sub-link defining detailed meshes for collision with environment -->
  <link name="arm_1_fr3_link2">
    <visual name="arm_1_fr3_link2_visual">
      <geometry>
        <mesh filename="../meshes/link2.stl"/>
      </geometry>
    </visual>
    <collision name="arm_1_fr3_link2_collision">
      <geometry>
        <mesh filename="../meshes/link2.stl"/>
      </geometry>
    </collision>
    <inertial>
      <origin rpy="0 0 0" xyz="0.0031828864 -0.0743221644 0.0088146084"/>
      <mass value="2.9355370338"/>
      <inertia ixx="0.041938946257609425" ixy="0.00020257331521090626" ixz="0.004077784227179924" iyy="0.02514514885014724" iyz="-0.0042252158006570156" izz="0.06170214472888839"/>
    </inertial>
  </link>
  <joint name="arm_1_fr3_joint2" type="revolute">
    <origin rpy="-1.570796326794897 0 0" xyz="0 0 0"/>
    <parent link="arm_1_fr3_link1"/>
    <child link="arm_1_fr3_link2"/>
    <axis xyz="0 0 1"/>
    <limit effort="87.0" lower="-1.7837" upper="1.7837" velocity="2.62"/>
    <safety_controller k_position="100.0" k_velocity="40.0" soft_lower_limit="-1.7837" soft_upper_limit="1.7837"/>
    <dynamics D="1" K="7000" damping="0.003" friction="0.2" mu_coulomb="0" mu_viscous="16"/>
  </joint>
  <!-- sub-link defining detailed meshes for collision with environment -->
  <link name="arm_1_fr3_link3">
    <visual name="arm_1_fr3_link3_visual">
      <geometry>
        <mesh filename="../meshes/link3.stl"/>
      </geometry>
    </visual>
    <collision name="arm_1_fr3_link3_collision">
      <geometry>
        <mesh filename="../meshes/link3.stl"/>
      </geometry>
    </collision>
    <inertial>
      <origin rpy="0 0 0" xyz="0.0407015686 -0.0048200565 -0.0289730823"/>
      <mass value="2.2449013699"/>
      <inertia ixx="0.02410142547240885" ixy="0.002404694559042109" ixz="-0.002856269270114313" iyy="0.01974053266708178" iyz="-0.002104212683891874" izz="0.019044494482244823"/>
    </inertial>
  </link>
  <joint name="arm_1_fr3_joint3" type="revolute">
    <origin rpy="1.570796326794897 0 0" xyz="0 -0.316 0"/>
    <parent link="arm_1_fr3_link2"/>
    <child link="arm_1_fr3_link3"/>
    <axis xyz="0 0 1"/>
    <limit effort="87.0" lower="-2.9007" upper="2.9007" velocity="2.62"/>
    <safety_controller k_position="100.0" k_velocity="40.0" soft_lower_limit="-2.9007" soft_upper_limit="2.9007"/>
    <dynamics D="1" K="7000" damping="0.003" friction="0.2" mu_coulomb="0" mu_viscous="16"/>
  </joint>
  <!-- sub-link defining detailed meshes for collision with environment -->
  <link name="arm_1_fr3_link4">
    <visual name="arm_1_fr3_link4_visual">
      <geometry>
        <mesh filename="../meshes/link4.stl"/>
      </geometry>
    </visual>
    <collision name="arm_1_fr3_link4_collision">
      <geometry>
        <mesh filename="../meshes/link4.stl"/>
      </geometry>
    </collision>
    <inertial>
      <origin rpy="0 0 0" xyz="-0.0459100965 0.0630492960 -0.0085187868"/>
      <mass value="2.6155955791"/>
      <inertia ixx="0.03452998321913202" ixy="0.01322552265982813" ixz="0.01015142998484113" iyy="0.028881621933049058" iyz="-0.0009762833870704552" izz="0.04125471171146641"/>
    </inertial>
  </link>
  <joint name="arm_1_fr3_joint4" type="revolute">
    <origin rpy="1.570796326794897 0 0" xyz="0.0825 0 0"/>
    <parent link="arm_1_fr3_link3"/>
    <child link="arm_1_fr3_link4"/>
    <axis xyz="0 0 1"/>
    <limit effort="87.0" lower="-3.0421" upper="-0.1518" velocity="2.62"/>
    <safety_controller k_position="100.0" k_velocity="40.0" soft_lower_limit="-3.0421" soft_upper_limit="-0.1518"/>
    <dynamics D="1" K="7000" damping="0.003" friction="0.2" mu_coulomb="0" mu_viscous="16"/>
  </joint>
  <!-- sub-link defining detailed meshes for collision with environment -->
  <link name="arm_1_fr3_link5">
    <visual name="arm_1_fr3_link5_visual">
      <geometry>
        <mesh filename="../meshes/link5.stl"/>
      </geometry>
    </visual>
    <collision name="arm_1_fr3_link5_collision">
      <geometry>
        <mesh filename="../meshes/link5.stl"/>
      </geometry>
    </collision>
    <inertial>
      <origin rpy="0 0 0" xyz="-0.0016039605 0.0292536262 -0.0972965990"/>
      <mass value="2.3271207594"/>
      <inertia ixx="0.051610278463662895" ixy="-0.005715173387783472" ixz="-0.0035673167625872135" iyy="0.04787729713371481" iyz="0.010673985108535986" izz="0.016423625579357254"/>
    </inertial>
  </link>
  <joint name="arm_1_fr3_joint5" type="revolute">
    <origin rpy="-1.570796326794897 0 0" xyz="-0.0825 0.384 0"/>
    <parent link="arm_1_fr3_link4"/>
    <child link="arm_1_fr3_link5"/>
    <axis xyz="0 0 1"/>
    <limit effort="12.0" lower="-2.8065" upper="2.8065" velocity="5.26"/>
    <safety_controller k_position="100.0" k_velocity="40.0" soft_lower_limit="-2.8065" soft_upper_limit="2.8065"/>
    <dynamics D="1" K="7000" damping="0.003" friction="0.2" mu_coulomb="0" mu_viscous="16"/>
  </joint>
  <!-- sub-link defining detailed meshes for collision with environment -->
  <link name="arm_1_fr3_link6">
    <visual name="arm_1_fr3_link6_visual">
      <geometry>
        <mesh filename="../meshes/link6.stl"/>
      </geometry>
    </visual>
    <collision name="arm_1_fr3_link6_collision">
      <geometry>
        <mesh filename="../meshes/link6.stl"/>
      </geometry>
    </collision>
    <inertial>
      <origin rpy="0 0 0" xyz="0.0597131221 -0.0410294666 -0.0101692726"/>
      <mass value="1.8170376524"/>
      <inertia ixx="0.005412333594383447" ixy="0.006193456360285834" ixz="0.0014219289306117652" iyy="0.014058329545509979" iyz="-0.0013140753741120031" izz="0.016080817924212554"/>
    </inertial>
  </link>
  <joint name="arm_1_fr3_joint6" type="revolute">
    <origin rpy="1.570796326794897 0 0" xyz="0 0 0"/>
    <parent link="arm_1_fr3_link5"/>
    <child link="arm_1_fr3_link6"/>
    <axis xyz="0 0 1"/>
    <limit effort="12.0" lower="0.5445" upper="4.5169" velocity="4.18"/>
    <safety_controller k_position="100.0" k_velocity="40.0" soft_lower_limit="0.5445" soft_upper_limit="4.5169"/>
    <dynamics D="1" K="7000" damping="0.003" friction="0.2" mu_coulomb="0" mu_viscous="16"/>
  </joint>
  <!-- sub-link defining detailed meshes for collision with environment -->
  <link name="arm_1_fr3_link7">
    <visual name="arm_1_fr3_link7_visual">
      <geometry>
        <mesh filename="../meshes/link7.stl"/>
      </geometry>
    </visual>
    <collision name="arm_1_fr3_link7_collision">
      <geometry>
        <mesh filename="../meshes/link7.stl"/>
      </geometry>
    </collision>
    <inertial>
      <origin rpy="0 0 0" xyz="0.0045225817 0.0086261921 -0.0161633251"/>
      <mass value="0.6271432862"/>
      <inertia ixx="0.00021092389150104718" ixy="-2.433299114461931e-05" ixz="4.564480393778983e-05" iyy="0.00017718568002411474" iyz="8.744070223226438e-05" izz="5.993190599659971e-05"/>
    </inertial>
  </link>
  <joint name="arm_1_fr3_joint7" type="revolute">
    <origin rpy="1.570796326794897 0 0" xyz="0.088 0 0"/>
    <parent link="arm_1_fr3_link6"/>
    <child link="arm_1_fr3_link7"/>
    <axis xyz="0 0 1"/>
    <limit effort="12.0" lower="-3.0159" upper="3.0159" velocity="5.26"/>
    <safety_controller k_position="100.0" k_velocity="40.0" soft_lower_limit="-3.0159" soft_upper_limit="3.0159"/>
    <dynamics D="1" K="7000" damping="0.003" friction="0.2" mu_coulomb="0" mu_viscous="16"/>
  </joint>
  <link name="arm_1_fr3_link8"/>
  <joint name="arm_1_fr3_joint8" type="fixed">
    <origin rpy="0 0 0" xyz="0 0 0.107"/>
    <parent link="arm_1_fr3_link7"/>
    <child link="arm_1_fr3_link8"/>
  </joint>
  <joint name="arm_0_gripper_fr3_hand_joint" type="fixed">
    <parent link="arm_0_fr3_link8"/>
    <child link="arm_0_gripper_fr3_hand"/>
    <origin rpy="0 0 -0.7853981633974483" xyz="0 0 0"/>
  </joint>
  <!-- sub-link defining detailed meshes for collision with environment -->
  <link name="arm_0_gripper_fr3_hand">
    <visual name="arm_0_gripper_fr3_hand_visual">
      <geometry>
        <mesh filename="../meshes/hand.stl"/>
      </geometry>
    </visual>
    <collision name="arm_0_gripper_fr3_hand_collision">
      <geometry>
        <mesh filename="../meshes/hand.stl"/>
      </geometry>
    </collision>
    <inertial>
      <origin rpy="0 0 0" xyz="-0.0000376 0.0119128 0.0207260"/>
      <mass value="0.6544"/>
      <inertia ixx="0.00186" ixy="0.0" ixz="0.0" iyy="0.0003" iyz="-2e-05" izz="0.00174"/>
    </inertial>
  </link>
  <!-- Define the hand_tcp frame -->
  <link name="arm_0_gripper_fr3_hand_tcp"/>
  <joint name="arm_0_gripper_fr3_hand_tcp_joint" type="fixed">
    <origin rpy="0 0 0" xyz="0 0 0.1034"/>
    <parent link="arm_0_gripper_fr3_hand"/>
    <child link="arm_0_gripper_fr3_hand_tcp"/>
  </joint>
  <link name="arm_0_gripper_fr3_leftfinger">
    <visual name="arm_0_gripper_fr3_leftfinger_visual">
      <geometry>
        <mesh filename="../meshes/finger.stl"/>
      </geometry>
    </visual>
    <!-- screw mount -->
    <collision>
      <origin rpy="0 0 0" xyz="0 18.5e-3 11e-3"/>
      <geometry>
        <box size="22e-3 15e-3 20e-3"/>
      </geometry>
    </collision>
    <!-- cartriage sledge -->
    <collision>
      <origin rpy="0 0 0" xyz="0 6.8e-3 2.2e-3"/>
      <geometry>
        <box size="22e-3 8.8e-3 3.8e-3"/>
      </geometry>
    </collision>
    <!-- diagonal finger -->
    <collision>
      <origin rpy="0.5235987755982988 0 0" xyz="0 15.9e-3 28.35e-3"/>
      <geometry>
        <box size="17.5e-3 7e-3 23.5e-3"/>
      </geometry>
    </collision>
    <!-- rubber tip with which to grasp -->
    <collision>
      <origin rpy="0 0 0" xyz="0 7.58e-3 45.25e-3"/>
      <geometry>
        <box size="17.5e-3 15.2e-3 18.5e-3"/>
      </geometry>
    </collision>
    <inertial>
      <origin rpy="0 0 0" xyz="0 0.0152850 0.0219675"/>
      <mass value="0.0291"/>
      <inertia ixx="8.49e-06" ixy="0.0" ixz="0.0" iyy="8.53e-06" iyz="-1.06e-06" izz="1.77e-06"/>
    </inertial>
  </link>
  <link name="arm_0_gripper_fr3_rightfinger">
    <visual name="arm_0_gripper_fr3_rightfinger_visual">
      <origin rpy="0 0 0" xyz="0 0 0"/>
      <geometry>
        <mesh filename="../meshes/finger.stl"/>
      </geometry>
    </visual>
    <!-- screw mount -->
    <collision>
      <origin rpy="0 0 0" xyz="0 18.5e-3 11e-3"/>
      <geometry>
        <box size="22e-3 15e-3 20e-3"/>
      </geometry>
    </collision>
    <!-- cartriage sledge -->
    <collision>
      <origin rpy="0 0 0" xyz="0 6.8e-3 2.2e-3"/>
      <geometry>
        <box size="22e-3 8.8e-3 3.8e-3"/>
      </geometry>
    </collision>
    <!-- diagonal finger -->
    <collision>
      <origin rpy="-0.5235987755982988 0 3.141592653589793" xyz="0 15.9e-3 28.35e-3"/>
      <geometry>
        <box size="17.5e-3 7e-3 23.5e-3"/>
      </geometry>
    </collision>
    <!-- rubber tip with which to grasp -->
    <collision>
      <origin rpy="0 0 0" xyz="0 7.58e-3 45.25e-3"/>
      <geometry>
        <box size="17.5e-3 15.2e-3 18.5e-3"/>
      </geometry>
    </collision>
    <inertial>
      <origin rpy="0 0 0" xyz="0 0.0152850 0.0219675"/>
      <mass value="0.0291"/>
      <inertia ixx="8.49e-06" ixy="0.0" ixz="0.0" iyy="8.53e-06" iyz="-1.06e-06" izz="1.77e-06"/>
    </inertial>
  </link>
  <joint name="arm_0_gripper_fr3_finger_joint1" type="prismatic">
    <parent link="arm_0_gripper_fr3_hand"/>
    <child link="arm_0_gripper_fr3_leftfinger"/>
    <origin rpy="0 0 0" xyz="0 0 0.0584"/>
    <axis xyz="0 1 0"/>
    <limit effort="100" lower="0.0" upper="0.04" velocity="0.2"/>
    <dynamics damping="0.3"/>
  </joint>
  <joint name="arm_0_gripper_fr3_finger_joint2" type="prismatic">
    <parent link="arm_0_gripper_fr3_hand"/>
    <child link="arm_0_gripper_fr3_rightfinger"/>
    <origin rpy="0 0 3.141592653589793" xyz="0 0 0.0584"/>
    <axis xyz="0 1 0"/>
    <limit effort="100" lower="0.0" upper="0.04" velocity="0.2"/>
    <mimic joint="arm_0_gripper_fr3_finger_joint1"/>
    <dynamics damping="0.3"/>
  </joint>
  <joint name="arm_1_gripper_fr3_hand_joint" type="fixed">
    <parent link="arm_1_fr3_link8"/>
    <child link="arm_1_gripper_fr3_hand"/>
    <origin rpy="0 0 -0.7853981633974483" xyz="0 0 0"/>
  </joint>
  <!-- sub-link defining detailed meshes for collision with environment -->
  <link name="arm_1_gripper_fr3_hand">
    <visual name="arm_1_gripper_fr3_hand_visual">
      <geometry>
        <mesh filename="../meshes/hand.stl"/>
      </geometry>
    </visual>
    <collision name="arm_1_gripper_fr3_hand_collision">
      <geometry>
        <mesh filename="../meshes/hand.stl"/>
      </geometry>
    </collision>
    <inertial>
      <origin rpy="0 0 0" xyz="-0.0000376 0.0119128 0.0207260"/>
      <mass value="0.6544"/>
      <inertia ixx="0.00186" ixy="0.0" ixz="0.0" iyy="0.0003" iyz="-2e-05" izz="0.00174"/>
    </inertial>
  </link>
  <!-- Define the hand_tcp frame -->
  <link name="arm_1_gripper_fr3_hand_tcp"/>
  <joint name="arm_1_gripper_fr3_hand_tcp_joint" type="fixed">
    <origin rpy="0 0 0" xyz="0 0 0.1034"/>
    <parent link="arm_1_gripper_fr3_hand"/>
    <child link="arm_1_gripper_fr3_hand_tcp"/>
  </joint>
  <link name="arm_1_gripper_fr3_leftfinger">
    <visual name="arm_1_gripper_fr3_leftfinger_visual">
      <geometry>
        <mesh filename="../meshes/finger.stl"/>
      </geometry>
    </visual>
    <!-- screw mount -->
    <collision>
      <origin rpy="0 0 0" xyz="0 18.5e-3 11e-3"/>
      <geometry>
        <box size="22e-3 15e-3 20e-3"/>
      </geometry>
    </collision>
    <!-- cartriage sledge -->
    <collision>
      <origin rpy="0 0 0" xyz="0 6.8e-3 2.2e-3"/>
      <geometry>
        <box size="22e-3 8.8e-3 3.8e-3"/>
      </geometry>
    </collision>
    <!-- diagonal finger -->
    <collision>
      <origin rpy="0.5235987755982988 0 0" xyz="0 15.9e-3 28.35e-3"/>
      <geometry>
        <box size="17.5e-3 7e-3 23.5e-3"/>
      </geometry>
    </collision>
    <!-- rubber tip with which to grasp -->
    <collision>
      <origin rpy="0 0 0" xyz="0 7.58e-3 45.25e-3"/>
      <geometry>
        <box size="17.5e-3 15.2e-3 18.5e-3"/>
      </geometry>
    </collision>
    <inertial>
      <origin rpy="0 0 0" xyz="0 0.0152850 0.0219675"/>
      <mass value="0.0291"/>
      <inertia ixx="8.49e-06" ixy="0.0" ixz="0.0" iyy="8.53e-06" iyz="-1.06e-06" izz="1.77e-06"/>
    </inertial>
  </link>
  <link name="arm_1_gripper_fr3_rightfinger">
    <visual name="arm_1_gripper_fr3_rightfinger_visual">
      <origin rpy="0 0 0" xyz="0 0 0"/>
      <geometry>
        <mesh filename="../meshes/finger.stl"/>
      </geometry>
    </visual>
    <!-- screw mount -->
    <collision>
      <origin rpy="0 0 0" xyz="0 18.5e-3 11e-3"/>
      <geometry>
        <box size="22e-3 15e-3 20e-3"/>
      </geometry>
    </collision>
    <!-- cartriage sledge -->
    <collision>
      <origin rpy="0 0 0" xyz="0 6.8e-3 2.2e-3"/>
      <geometry>
        <box size="22e-3 8.8e-3 3.8e-3"/>
      </geometry>
    </collision>
    <!-- diagonal finger -->
    <collision>
      <origin rpy="-0.5235987755982988 0 3.141592653589793" xyz="0 15.9e-3 28.35e-3"/>
      <geometry>
        <box size="17.5e-3 7e-3 23.5e-3"/>
      </geometry>
    </collision>
    <!-- rubber tip with which to grasp -->
    <collision>
      <origin rpy="0 0 0" xyz="0 7.58e-3 45.25e-3"/>
      <geometry>
        <box size="17.5e-3 15.2e-3 18.5e-3"/>
      </geometry>
    </collision>
    <inertial>
      <origin rpy="0 0 0" xyz="0 0.0152850 0.0219675"/>
      <mass value="0.0291"/>
      <inertia ixx="8.49e-06" ixy="0.0" ixz="0.0" iyy="8.53e-06" iyz="-1.06e-06" izz="1.77e-06"/>
    </inertial>
  </link>
  <joint name="arm_1_gripper_fr3_finger_joint1" type="prismatic">
    <parent link="arm_1_gripper_fr3_hand"/>
    <child link="arm_1_gripper_fr3_leftfinger"/>
    <origin rpy="0 0 0" xyz="0 0 0.0584"/>
    <axis xyz="0 1 0"/>
    <limit effort="100" lower="0.0" upper="0.04" velocity="0.2"/>
    <dynamics damping="0.3"/>
  </joint>
  <joint name="arm_1_gripper_fr3_finger_joint2" type="prismatic">
    <parent link="arm_1_gripper_fr3_hand"/>
    <child link="arm_1_gripper_fr3_rightfinger"/>
    <origin rpy="0 0 3.141592653589793" xyz="0 0 0.0584"/>
    <axis xyz="0 1 0"/>
    <limit effort="100" lower="0.0" upper="0.04" velocity="0.2"/>
    <mimic joint="arm_1_gripper_fr3_finger_joint1"/>
    <dynamics damping="0.3"/>
  </joint>
</robot>
